Workbook

Sheet 文本计算
A1: Some kids walk to school, while others catch a bus or take the train. But in 1954, eight-year-old Farrokh had to get on a ship to go to his new school! He caught a train that rattled and jolted its way out of the dusty city and into the lush green hills. He couldn’t help thinking that he was getting further away from his family with every mile… What would it be like at his new school? He worried about this for the whole journey. He was also anxious that the other pupils might make fun of his teeth. Would anybody want to be his friend? After a bone-shaking journey, he and nineteen other new students found themselves at the gates of St Peter’s School in Panchgani. It looked very nice, with red-roofed buildings surrounded by beautiful green gardens. Above the gate was the school’s symbol – a bird rising out of the flames. Farrokh knew that it was the mythical phoenix, which was reborn out of a fire. He felt inspired by the wonderful creature! The teachers welcomed the students in and showed them their dormitory. That night, the boy couldn’t get to sleep because he missed his family so much... Farrokh didn’t realise that many of the other boys felt just as lonely as he did! He eventually plucked up the courage to start chatting with the other pupils, covering his teeth with his hand. He soon made some new friends! His teachers believed that the best way to help students who were homesick was to distract them with sports and activities. Farrokh tried boxing and chess and ping pong – and discovered that he was good at all of them. He also loved to win! Then there were drama classes! Though Farrokh felt nervous when talking to others, it was different when he stepped onto the stage. The boy loved putting on costumes and swaggering around like royalty! Even better than drama, though, was music! The students had to take part in choir practice, and that was when the music teacher noticed that Farrokh had an extraordinary voice. He hit every note perfectly! “I think you should have piano lessons!” the music teacher told him. His tutor taught him about jazz and classical music, which were wonderful to listen to. | G1: 请在左侧单元格内黏贴文本， 文本总数小于1000词符。
A2: 文本总体数据情况一览
A3: 文本词符总数 | B3: 去重词符总数 | C3: 去重词符占比 | D3: 课标词符总数 | E3: 超课标词符总数 | F3: 课标词符占比
A4: ='text process sheet'!I1 -> 390 | B4: ='text process sheet'!G1002 -> 214 | C4: =B4/A4 -> 0.54871795 | D4: =A6+C6+E6 -> 365 | E4: =A4-D4 -> 25 | F4: =D4/A4 -> 0.93589744
A5: 义教词符数 | B5: 义教词符词符占比 | C5: 必修词符数 | D5: 必修词符占比 | E5: 选择性必修词符数 | F5: 选择性必修词符占比
A6: =义教!B10000 -> 345 | B6: =A6/A4 -> 0.88461538 | C6: =必修!B14000 -> 8 | D6: =C6/A4 -> 0.020512821 | E6: =选择性必修!B8000 -> 12 | F6: =E6/A4 -> 0.030769231
A8: 文本词汇分级统计情况汇总
A9: 文本字符 | B9: 频次（课标词符） | C9: 频次（义教） | D9: 频次（必修） | E9: 频次（选择性必修） | F9: 常用合成词 | G9: 考纲3500词 | H9: 文本字符
A10: ='text process sheet'!F1 -> Some | B10: =IF(SUM(C10:E10)=0,"no",SUM(C10:E10)) -> 2 | C10: =IFERROR(VLOOKUP(A10,义教!A:B,2,FALSE),"no") -> 2 | D10: =IFERROR(VLOOKUP(A10,必修!A:B,2,FALSE),"no") -> 0 | E10: =IFERROR(VLOOKUP(A10,选择性必修!A:B,2,FALSE),"no") -> no | F10: =IFERROR(VLOOKUP(A10,合成词!A:B,2,FALSE),"no") -> no | G10: =IFERROR(VLOOKUP(A10,'3500'!A:D,2,FALSE),"no") -> 2 | H10: =A10 -> Some
A11: ='text process sheet'!F2 -> kids | B11: =IF(SUM(C11:E11)=0,"no",SUM(C11:E11)) -> 1 | C11: =IFERROR(VLOOKUP(A11,义教!A:B,2,FALSE),"no") -> 1 | D11: =IFERROR(VLOOKUP(A11,必修!A:B,2,FALSE),"no") -> no | E11: =IFERROR(VLOOKUP(A11,选择性必修!A:B,2,FALSE),"no") -> no | F11: =IFERROR(VLOOKUP(A11,合成词!A:B,2,FALSE),"no") -> no | G11: =IFERROR(VLOOKUP(A11,'3500'!A:D,2,FALSE),"no") -> 1 | H11: =A11 -> kids
A12: ='text process sheet'!F3 -> walk | B12: =IF(SUM(C12:E12)=0,"no",SUM(C12:E12)) -> 1 | C12: =IFERROR(VLOOKUP(A12,义教!A:B,2,FALSE),"no") -> 1 | D12: =IFERROR(VLOOKUP(A12,必修!A:B,2,FALSE),"no") -> no | E12: =IFERROR(VLOOKUP(A12,选择性必修!A:B,2,FALSE),"no") -> no | F12: =IFERROR(VLOOKUP(A12,合成词!A:B,2,FALSE),"no") -> no | G12: =IFERROR(VLOOKUP(A12,'3500'!A:D,2,FALSE),"no") -> 1 | H12: =A12 -> walk
A13: ='text process sheet'!F4 -> to | B13: =IF(SUM(C13:E13)=0,"no",SUM(C13:E13)) -> 13 | C13: =IFERROR(VLOOKUP(A13,义教!A:B,2,FALSE),"no") -> 13 | D13: =IFERROR(VLOOKUP(A13,必修!A:B,2,FALSE),"no") -> 0 | E13: =IFERROR(VLOOKUP(A13,选择性必修!A:B,2,FALSE),"no") -> no | F13: =IFERROR(VLOOKUP(A13,合成词!A:B,2,FALSE),"no") -> no | G13: =IFERROR(VLOOKUP(A13,'3500'!A:D,2,FALSE),"no") -> 13 | H13: =A13 -> to
A14: ='text process sheet'!F5 -> school | B14: =IF(SUM(C14:E14)=0,"no",SUM(C14:E14)) -> 5 | C14: =IFERROR(VLOOKUP(A14,义教!A:B,2,FALSE),"no") -> 5 | D14: =IFERROR(VLOOKUP(A14,必修!A:B,2,FALSE),"no") -> no | E14: =IFERROR(VLOOKUP(A14,选择性必修!A:B,2,FALSE),"no") -> no | F14: =IFERROR(VLOOKUP(A14,合成词!A:B,2,FALSE),"no") -> no | G14: =IFERROR(VLOOKUP(A14,'3500'!A:D,2,FALSE),"no") -> 5 | H14: =A14 -> school
A15: ='text process sheet'!F6 -> while | B15: =IF(SUM(C15:E15)=0,"no",SUM(C15:E15)) -> 1 | C15: =IFERROR(VLOOKUP(A15,义教!A:B,2,FALSE),"no") -> 1 | D15: =IFERROR(VLOOKUP(A15,必修!A:B,2,FALSE),"no") -> no | E15: =IFERROR(VLOOKUP(A15,选择性必修!A:B,2,FALSE),"no") -> no | F15: =IFERROR(VLOOKUP(A15,合成词!A:B,2,FALSE),"no") -> no | G15: =IFERROR(VLOOKUP(A15,'3500'!A:D,2,FALSE),"no") -> 1 | H15: =A15 -> while
A16: ='text process sheet'!F7 -> others | B16: =IF(SUM(C16:E16)=0,"no",SUM(C16:E16)) -> 2 | C16: =IFERROR(VLOOKUP(A16,义教!A:B,2,FALSE),"no") -> 2 | D16: =IFERROR(VLOOKUP(A16,必修!A:B,2,FALSE),"no") -> no | E16: =IFERROR(VLOOKUP(A16,选择性必修!A:B,2,FALSE),"no") -> no | F16: =IFERROR(VLOOKUP(A16,合成词!A:B,2,FALSE),"no") -> no | G16: =IFERROR(VLOOKUP(A16,'3500'!A:D,2,FALSE),"no") -> 2 | H16: =A16 -> others
A17: ='text process sheet'!F8 -> catch | B17: =IF(SUM(C17:E17)=0,"no",SUM(C17:E17)) -> 1 | C17: =IFERROR(VLOOKUP(A17,义教!A:B,2,FALSE),"no") -> 1 | D17: =IFERROR(VLOOKUP(A17,必修!A:B,2,FALSE),"no") -> no | E17: =IFERROR(VLOOKUP(A17,选择性必修!A:B,2,FALSE),"no") -> no | F17: =IFERROR(VLOOKUP(A17,合成词!A:B,2,FALSE),"no") -> no | G17: =IFERROR(VLOOKUP(A17,'3500'!A:D,2,FALSE),"no") -> 1 | H17: =A17 -> catch
A18: ='text process sheet'!F9 -> a | B18: =IF(SUM(C18:E18)=0,"no",SUM(C18:E18)) -> 6 | C18: =IFERROR(VLOOKUP(A18,义教!A:B,2,FALSE),"no") -> 6 | D18: =IFERROR(VLOOKUP(A18,必修!A:B,2,FALSE),"no") -> no | E18: =IFERROR(VLOOKUP(A18,选择性必修!A:B,2,FALSE),"no") -> no | F18: =IFERROR(VLOOKUP(A18,合成词!A:B,2,FALSE),"no") -> no | G18: =IFERROR(VLOOKUP(A18,'3500'!A:D,2,FALSE),"no") -> 6 | H18: =A18 -> a
A19: ='text process sheet'!F10 -> bus | B19: =IF(SUM(C19:E19)=0,"no",SUM(C19:E19)) -> 1 | C19: =IFERROR(VLOOKUP(A19,义教!A:B,2,FALSE),"no") -> 1 | D19: =IFERROR(VLOOKUP(A19,必修!A:B,2,FALSE),"no") -> no | E19: =IFERROR(VLOOKUP(A19,选择性必修!A:B,2,FALSE),"no") -> no | F19: =IFERROR(VLOOKUP(A19,合成词!A:B,2,FALSE),"no") -> no | G19: =IFERROR(VLOOKUP(A19,'3500'!A:D,2,FALSE),"no") -> 1 | H19: =A19 -> bus
A20: ='text process sheet'!F11 -> or | B20: =IF(SUM(C20:E20)=0,"no",SUM(C20:E20)) -> 1 | C20: =IFERROR(VLOOKUP(A20,义教!A:B,2,FALSE),"no") -> 1 | D20: =IFERROR(VLOOKUP(A20,必修!A:B,2,FALSE),"no") -> no | E20: =IFERROR(VLOOKUP(A20,选择性必修!A:B,2,FALSE),"no") -> no | F20: =IFERROR(VLOOKUP(A20,合成词!A:B,2,FALSE),"no") -> no | G20: =IFERROR(VLOOKUP(A20,'3500'!A:D,2,FALSE),"no") -> 1 | H20: =A20 -> or
A21: ='text process sheet'!F12 -> take | B21: =IF(SUM(C21:E21)=0,"no",SUM(C21:E21)) -> 2 | C21: =IFERROR(VLOOKUP(A21,义教!A:B,2,FALSE),"no") -> 2 | D21: =IFERROR(VLOOKUP(A21,必修!A:B,2,FALSE),"no") -> no | E21: =IFERROR(VLOOKUP(A21,选择性必修!A:B,2,FALSE),"no") -> no | F21: =IFERROR(VLOOKUP(A21,合成词!A:B,2,FALSE),"no") -> no | G21: =IFERROR(VLOOKUP(A21,'3500'!A:D,2,FALSE),"no") -> 2 | H21: =A21 -> take
... A1010: ='text process sheet'!F1001 | B1010: =IF(SUM(C1010:E1010)=0,"no",SUM(C1010:E1010)) -> no | C1010: =IFERROR(VLOOKUP(A1010,义教!A:B,2,FALSE),"no") -> no | D1010: =IFERROR(VLOOKUP(A1010,必修!A:B,2,FALSE),"no") -> no | E1010: =IFERROR(VLOOKUP(A1010,选择性必修!A:B,2,FALSE),"no") -> no | F1010: =IFERROR(VLOOKUP(A1010,合成词!A:B,2,FALSE),"no") -> no | G1010: =IFERROR(VLOOKUP(A1010,'3500'!A:D,2,FALSE),"no") -> no | H1010: =A1010

Sheet 超纲词汇总
A1: 超纲词 | B1: 频次
A2: {=IFERROR(INDEX(文本计算!$A$9:$A$1010,SMALL(IF(文本计算!$B$9:$B$1010="no",ROW(文本计算!$B$9:$B$1010)-ROW(文本计算!$B$9)+1),ROW(1:1))),"")} -> Farrokh | B2: =IF(A2="","",COUNTIF('text process sheet'!C:C,A2)) -> 6
A3: {=IFERROR(INDEX(文本计算!$A$9:$A$1010,SMALL(IF(文本计算!$B$9:$B$1010="no",ROW(文本计算!$B$9:$B$1010)-ROW(文本计算!$B$9)+1),ROW(2:2))),"")} -> rattled | B3: =IF(A3="","",COUNTIF('text process sheet'!C:C,A3)) -> 1
A4: {=IFERROR(INDEX(文本计算!$A$9:$A$1010,SMALL(IF(文本计算!$B$9:$B$1010="no",ROW(文本计算!$B$9:$B$1010)-ROW(文本计算!$B$9)+1),ROW(3:3))),"")} -> jolted | B4: =IF(A4="","",COUNTIF('text process sheet'!C:C,A4)) -> 1
A5: {=IFERROR(INDEX(文本计算!$A$9:$A$1010,SMALL(IF(文本计算!$B$9:$B$1010="no",ROW(文本计算!$B$9:$B$1010)-ROW(文本计算!$B$9)+1),ROW(4:4))),"")} -> lush | B5: =IF(A5="","",COUNTIF('text process sheet'!C:C,A5)) -> 1
A6: {=IFERROR(INDEX(文本计算!$A$9:$A$1010,SMALL(IF(文本计算!$B$9:$B$1010="no",ROW(文本计算!$B$9:$B$1010)-ROW(文本计算!$B$9)+1),ROW(5:5))),"")} -> mile… | B6: =IF(A6="","",COUNTIF('text process sheet'!C:C,A6)) -> 1
A7: {=IFERROR(INDEX(文本计算!$A$9:$A$1010,SMALL(IF(文本计算!$B$9:$B$1010="no",ROW(文本计算!$B$9:$B$1010)-ROW(文本计算!$B$9)+1),ROW(6:6))),"")} -> Peter | B7: =IF(A7="","",COUNTIF('text process sheet'!C:C,A7)) -> 1
A8: {=IFERROR(INDEX(文本计算!$A$9:$A$1010,SMALL(IF(文本计算!$B$9:$B$1010="no",ROW(文本计算!$B$9:$B$1010)-ROW(文本计算!$B$9)+1),ROW(7:7))),"")} -> Panchgani | B8: =IF(A8="","",COUNTIF('text process sheet'!C:C,A8)) -> 1
A9: {=IFERROR(INDEX(文本计算!$A$9:$A$1010,SMALL(IF(文本计算!$B$9:$B$1010="no",ROW(文本计算!$B$9:$B$1010)-ROW(文本计算!$B$9)+1),ROW(8:8))),"")} -> – | B9: =IF(A9="","",COUNTIF('text process sheet'!C:C,A9)) -> 2
A10: {=IFERROR(INDEX(文本计算!$A$9:$A$1010,SMALL(IF(文本计算!$B$9:$B$1010="no",ROW(文本计算!$B$9:$B$1010)-ROW(文本计算!$B$9)+1),ROW(9:9))),"")} -> flames | B10: =IF(A10="","",COUNTIF('text process sheet'!C:C,A10)) -> 1
A11: {=IFERROR(INDEX(文本计算!$A$9:$A$1010,SMALL(IF(文本计算!$B$9:$B$1010="no",ROW(文本计算!$B$9:$B$1010)-ROW(文本计算!$B$9)+1),ROW(10:10))),"")} -> mythical | B11: =IF(A11="","",COUNTIF('text process sheet'!C:C,A11)) -> 1
A12: {=IFERROR(INDEX(文本计算!$A$9:$A$1010,SMALL(IF(文本计算!$B$9:$B$1010="no",ROW(文本计算!$B$9:$B$1010)-ROW(文本计算!$B$9)+1),ROW(11:11))),"")} -> phoenix | B12: =IF(A12="","",COUNTIF('text process sheet'!C:C,A12)) -> 1
A13: {=IFERROR(INDEX(文本计算!$A$9:$A$1010,SMALL(IF(文本计算!$B$9:$B$1010="no",ROW(文本计算!$B$9:$B$1010)-ROW(文本计算!$B$9)+1),ROW(12:12))),"")} -> plucked | B13: =IF(A13="","",COUNTIF('text process sheet'!C:C,A13)) -> 1
A14: {=IFERROR(INDEX(文本计算!$A$9:$A$1010,SMALL(IF(文本计算!$B$9:$B$1010="no",ROW(文本计算!$B$9:$B$1010)-ROW(文本计算!$B$9)+1),ROW(13:13))),"")} -> homesick | B14: =IF(A14="","",COUNTIF('text process sheet'!C:C,A14)) -> 1
A15: {=IFERROR(INDEX(文本计算!$A$9:$A$1010,SMALL(IF(文本计算!$B$9:$B$1010="no",ROW(文本计算!$B$9:$B$1010)-ROW(文本计算!$B$9)+1),ROW(14:14))),"")} -> distract | B15: =IF(A15="","",COUNTIF('text process sheet'!C:C,A15)) -> 1
A16: {=IFERROR(INDEX(文本计算!$A$9:$A$1010,SMALL(IF(文本计算!$B$9:$B$1010="no",ROW(文本计算!$B$9:$B$1010)-ROW(文本计算!$B$9)+1),ROW(15:15))),"")} -> ping | B16: =IF(A16="","",COUNTIF('text process sheet'!C:C,A16)) -> 1
A17: {=IFERROR(INDEX(文本计算!$A$9:$A$1010,SMALL(IF(文本计算!$B$9:$B$1010="no",ROW(文本计算!$B$9:$B$1010)-ROW(文本计算!$B$9)+1),ROW(16:16))),"")} -> pong | B17: =IF(A17="","",COUNTIF('text process sheet'!C:C,A17)) -> 1
A18: {=IFERROR(INDEX(文本计算!$A$9:$A$1010,SMALL(IF(文本计算!$B$9:$B$1010="no",ROW(文本计算!$B$9:$B$1010)-ROW(文本计算!$B$9)+1),ROW(17:17))),"")} -> swaggering | B18: =IF(A18="","",COUNTIF('text process sheet'!C:C,A18)) -> 1
A19: {=IFERROR(INDEX(文本计算!$A$9:$A$1010,SMALL(IF(文本计算!$B$9:$B$1010="no",ROW(文本计算!$B$9:$B$1010)-ROW(文本计算!$B$9)+1),ROW(18:18))),"")} -> choir | B19: =IF(A19="","",COUNTIF('text process sheet'!C:C,A19)) -> 1
A20: {=IFERROR(INDEX(文本计算!$A$9:$A$1010,SMALL(IF(文本计算!$B$9:$B$1010="no",ROW(文本计算!$B$9:$B$1010)-ROW(文本计算!$B$9)+1),ROW(19:19))),"")} -> tutor | B20: =IF(A20="","",COUNTIF('text process sheet'!C:C,A20)) -> 1
A21: {=IFERROR(INDEX(文本计算!$A$9:$A$1010,SMALL(IF(文本计算!$B$9:$B$1010="no",ROW(文本计算!$B$9:$B$1010)-ROW(文本计算!$B$9)+1),ROW(20:20))),"")} | B21: =IF(A21="","",COUNTIF('text process sheet'!C:C,A21))
A22: {=IFERROR(INDEX(文本计算!$A$9:$A$1010,SMALL(IF(文本计算!$B$9:$B$1010="no",ROW(文本计算!$B$9:$B$1010)-ROW(文本计算!$B$9)+1),ROW(21:21))),"")} | B22: =IF(A22="","",COUNTIF('text process sheet'!C:C,A22))
A23: {=IFERROR(INDEX(文本计算!$A$9:$A$1010,SMALL(IF(文本计算!$B$9:$B$1010="no",ROW(文本计算!$B$9:$B$1010)-ROW(文本计算!$B$9)+1),ROW(22:22))),"")} | B23: =IF(A23="","",COUNTIF('text process sheet'!C:C,A23))
A24: {=IFERROR(INDEX(文本计算!$A$9:$A$1010,SMALL(IF(文本计算!$B$9:$B$1010="no",ROW(文本计算!$B$9:$B$1010)-ROW(文本计算!$B$9)+1),ROW(23:23))),"")} | B24: =IF(A24="","",COUNTIF('text process sheet'!C:C,A24))
A25: {=IFERROR(INDEX(文本计算!$A$9:$A$1010,SMALL(IF(文本计算!$B$9:$B$1010="no",ROW(文本计算!$B$9:$B$1010)-ROW(文本计算!$B$9)+1),ROW(24:24))),"")} | B25: =IF(A25="","",COUNTIF('text process sheet'!C:C,A25))
A26: {=IFERROR(INDEX(文本计算!$A$9:$A$1010,SMALL(IF(文本计算!$B$9:$B$1010="no",ROW(文本计算!$B$9:$B$1010)-ROW(文本计算!$B$9)+1),ROW(25:25))),"")} | B26: =IF(A26="","",COUNTIF('text process sheet'!C:C,A26))
A27: {=IFERROR(INDEX(文本计算!$A$9:$A$1010,SMALL(IF(文本计算!$B$9:$B$1010="no",ROW(文本计算!$B$9:$B$1010)-ROW(文本计算!$B$9)+1),ROW(26:26))),"")} | B27: =IF(A27="","",COUNTIF('text process sheet'!C:C,A27))
A28: {=IFERROR(INDEX(文本计算!$A$9:$A$1010,SMALL(IF(文本计算!$B$9:$B$1010="no",ROW(文本计算!$B$9:$B$1010)-ROW(文本计算!$B$9)+1),ROW(27:27))),"")} | B28: =IF(A28="","",COUNTIF('text process sheet'!C:C,A28))
A29: {=IFERROR(INDEX(文本计算!$A$9:$A$1010,SMALL(IF(文本计算!$B$9:$B$1010="no",ROW(文本计算!$B$9:$B$1010)-ROW(文本计算!$B$9)+1),ROW(28:28))),"")} | B29: =IF(A29="","",COUNTIF('text process sheet'!C:C,A29))
A30: {=IFERROR(INDEX(文本计算!$A$9:$A$1010,SMALL(IF(文本计算!$B$9:$B$1010="no",ROW(文本计算!$B$9:$B$1010)-ROW(文本计算!$B$9)+1),ROW(29:29))),"")} | B30: =IF(A30="","",COUNTIF('text process sheet'!C:C,A30))
A31: {=IFERROR(INDEX(文本计算!$A$9:$A$1010,SMALL(IF(文本计算!$B$9:$B$1010="no",ROW(文本计算!$B$9:$B$1010)-ROW(文本计算!$B$9)+1),ROW(30:30))),"")} | B31: =IF(A31="","",COUNTIF('text process sheet'!C:C,A31))
A32: {=IFERROR(INDEX(文本计算!$A$9:$A$1010,SMALL(IF(文本计算!$B$9:$B$1010="no",ROW(文本计算!$B$9:$B$1010)-ROW(文本计算!$B$9)+1),ROW(31:31))),"")} | B32: =IF(A32="","",COUNTIF('text process sheet'!C:C,A32))
A33: {=IFERROR(INDEX(文本计算!$A$9:$A$1010,SMALL(IF(文本计算!$B$9:$B$1010="no",ROW(文本计算!$B$9:$B$1010)-ROW(文本计算!$B$9)+1),ROW(32:32))),"")} | B33: =IF(A33="","",COUNTIF('text process sheet'!C:C,A33))
A34: {=IFERROR(INDEX(文本计算!$A$9:$A$1010,SMALL(IF(文本计算!$B$9:$B$1010="no",ROW(文本计算!$B$9:$B$1010)-ROW(文本计算!$B$9)+1),ROW(33:33))),"")} | B34: =IF(A34="","",COUNTIF('text process sheet'!C:C,A34))
A35: {=IFERROR(INDEX(文本计算!$A$9:$A$1010,SMALL(IF(文本计算!$B$9:$B$1010="no",ROW(文本计算!$B$9:$B$1010)-ROW(文本计算!$B$9)+1),ROW(34:34))),"")} | B35: =IF(A35="","",COUNTIF('text process sheet'!C:C,A35))
A36: {=IFERROR(INDEX(文本计算!$A$9:$A$1010,SMALL(IF(文本计算!$B$9:$B$1010="no",ROW(文本计算!$B$9:$B$1010)-ROW(文本计算!$B$9)+1),ROW(35:35))),"")} | B36: =IF(A36="","",COUNTIF('text process sheet'!C:C,A36))
A37: {=IFERROR(INDEX(文本计算!$A$9:$A$1010,SMALL(IF(文本计算!$B$9:$B$1010="no",ROW(文本计算!$B$9:$B$1010)-ROW(文本计算!$B$9)+1),ROW(36:36))),"")} | B37: =IF(A37="","",COUNTIF('text process sheet'!C:C,A37))
A38: {=IFERROR(INDEX(文本计算!$A$9:$A$1010,SMALL(IF(文本计算!$B$9:$B$1010="no",ROW(文本计算!$B$9:$B$1010)-ROW(文本计算!$B$9)+1),ROW(37:37))),"")} | B38: =IF(A38="","",COUNTIF('text process sheet'!C:C,A38))
A39: {=IFERROR(INDEX(文本计算!$A$9:$A$1010,SMALL(IF(文本计算!$B$9:$B$1010="no",ROW(文本计算!$B$9:$B$1010)-ROW(文本计算!$B$9)+1),ROW(38:38))),"")} | B39: =IF(A39="","",COUNTIF('text process sheet'!C:C,A39))
A40: {=IFERROR(INDEX(文本计算!$A$9:$A$1010,SMALL(IF(文本计算!$B$9:$B$1010="no",ROW(文本计算!$B$9:$B$1010)-ROW(文本计算!$B$9)+1),ROW(39:39))),"")} | B40: =IF(A40="","",COUNTIF('text process sheet'!C:C,A40))
...

Sheet 作者信息
A1: 制作者 | B1: 徐使超
A2: 单位 | B2: 海宁市高级中学
A3: 地址 | B3: 海宁市赞山路1号
A4: 邮箱 | B4: jjjmk@126.com
A5: 制作时间 | B5: 202510

Sheet 使用说明
AT4: 第一步：在“文本计算”页A1(红框中）黏贴需要计算的语篇文本，移动点击其他单元格，或按回车结束。
AT8: 第二步：在“文本计算”页查看文本总体数据，以及单词在各类词表的分布情况，如显示为no则词表中不包含该单词，显示为数字则表示词表包含该单词，数字代表单词在文本中出现的次数。
AD43: 提示：在“超纲词汇总”页可查看文本中的所有课标（2020版本）外词汇，数字表示该单词在文本中出现的频次。 部分单词因受词族分类之限，由于词性变化，在词表中易被统计为超纲词，请以《课程标准》词汇表为准。

Sheet 更新日志
A1: 20250826 | B1: 词表整理，修改了不同词表中单词重复统计的问题

Sheet text process sheet
A1: =SUBSTITUTE(SUBSTITUTE(SUBSTITUTE(SUBSTITUTE(SUBSTITUTE(SUBSTITUTE(SUBSTITUTE(SUBSTITUTE(SUBSTITUTE(SUBSTITUTE(SUBSTITUTE(SUBSTITUTE(SUBSTITUTE(SUBSTITUTE(SUBSTITUTE(SUBSTITUTE(SUBSTITUTE(SUBSTITUTE(SUBSTITUTE(SUBSTITUTE(SUBSTITUTE(SUBSTITUTE(SUBSTITUTE(SUBSTITUTE(SUBSTITUTE(SUBSTITUTE(SUBSTITUTE(SUBSTITUTE(SUBSTITUTE(SUBSTITUTE(SUBSTITUTE(SUBSTITUTE(SUBSTITUTE(SUBSTITUTE(文本计算!A1,",",""),".",""),":",""),"!",""),"?",""),"""",""),CHAR(39)," "),";",""),"true","_true_"),"false","_false_"),"0",""),"1",""),"2",""),"3",""),"4",""),"5",""),"6",""),"7",""),"8",""),"9",""),"’"," "),CHAR(45)," "),"“",""),"”",""),"‘",""),"’"," "),"—"," ")," "," "),CHAR(8)," "),CHAR(10)," "),"-"," "),")"," "),"("," ")," "," ") -> Some kids walk to school while others catch a bus or take the train But in eight year old Farrokh had to get on a ship to go to his new school He caught a train that rattled and jolted its way out of the dusty city and into the lush green hills He couldn t help thinking that he was getting further away from his family with every mile… What would it be like at his new school He worried about this for the whole journey He was also anxious that the other pupils might make fun of his teeth Would anybody want to be his friend After a bone shaking journey he and nineteen other new students found themselves at the gates of St Peter s School in Panchgani It looked very nice with red roofed buildings surrounded by beautiful green gardens Above the gate was the school s symbol – a bird rising out of the flames Farrokh knew that it was the mythical phoenix which was reborn out of a fire He felt inspired by the wonderful creature The teachers welcomed the students in and showed them their dormitory That night the boy couldn t get to sleep because he missed his family so much Farrokh didn t realise that many of the other boys felt just as lonely as he did He eventually plucked up the courage to start chatting with the other pupils covering his teeth with his hand He soon made some new friends His teachers believed that the best way to help students who were homesick was to distract them with sports and activities Farrokh tried boxing and chess and ping pong – and discovered that he was good at all of them He also loved to win Then there were drama classes Though Farrokh felt nervous when talking to others it was different when he stepped onto the stage The boy loved putting on costumes and swaggering around like royalty Even better than drama though was music The students had to take part in choir practice and that was when the music teacher noticed that Farrokh had an extraordinary voice He hit every note perfectly I think you should have piano lessons the music teacher told him His tutor taught him about jazz and classical music which were wonderful to listen to | B1: =IFERROR(FIND(" ",A1,1),"_") -> 5 | C1: =IFERROR(MID(A1,1,FIND(" ",A1)-1),"-") -> Some | E1: =IF(C1="",0,1) -> 1 | F1: =INDEX(C:C,SMALL(IF(MATCH($C$1:$C$1001,$C$1:$C$1001,)=ROW($1:$1001),ROW($1:$1001),4^8),ROW(C1)))&"" -> Some | G1: =IF(F1="",0,1) -> 1 | I1: =SUM(E1:E2000) -> 390
B2: =IFERROR(B1+LEN(C2)+1,"-") -> 10 | C2: =IFERROR(MID($A$1,B1+1,FIND(" ",$A$1,B1+1)-B1-1),"-") -> kids | E2: =IF(C2="",0,1) -> 1 | F2: {=INDEX(C:C,SMALL(IF(MATCH($C$1:$C$1001,$C$1:$C$1001,)=ROW($1:$1001),ROW($1:$1001),4^8),ROW(C2)))&""} -> kids | G2: =IF(F2="",0,1) -> 1
B3: =IFERROR(B2+LEN(C3)+1,"-") -> 15 | C3: =IFERROR(MID($A$1,B2+1,FIND(" ",$A$1,B2+1)-B2-1),"-") -> walk | E3: =IF(C3="",0,1) -> 1 | F3: {=INDEX(C:C,SMALL(IF(MATCH($C$1:$C$1001,$C$1:$C$1001,)=ROW($1:$1001),ROW($1:$1001),4^8),ROW(C3)))&""} -> walk | G3: =IF(F3="",0,1) -> 1
B4: =IFERROR(B3+LEN(C4)+1,"") -> 18 | C4: =IFERROR(MID($A$1,B3+1,FIND(" ",$A$1,B3+1)-B3-1),"") -> to | E4: =IF(C4="",0,1) -> 1 | F4: {=INDEX(C:C,SMALL(IF(MATCH($C$1:$C$1001,$C$1:$C$1001,)=ROW($1:$1001),ROW($1:$1001),4^8),ROW(C4)))&""} -> to | G4: =IF(F4="",0,1) -> 1
B5: =IFERROR(B4+LEN(C5)+1,"") -> 25 | C5: =IFERROR(MID($A$1,B4+1,FIND(" ",$A$1,B4+1)-B4-1),"") -> school | E5: =IF(C5="",0,1) -> 1 | F5: {=INDEX(C:C,SMALL(IF(MATCH($C$1:$C$1001,$C$1:$C$1001,)=ROW($1:$1001),ROW($1:$1001),4^8),ROW(C5)))&""} -> school | G5: =IF(F5="",0,1) -> 1
B6: =IFERROR(B5+LEN(C6)+1,"") -> 31 | C6: =IFERROR(MID($A$1,B5+1,FIND(" ",$A$1,B5+1)-B5-1),"") -> while | E6: =IF(C6="",0,1) -> 1 | F6: {=INDEX(C:C,SMALL(IF(MATCH($C$1:$C$1001,$C$1:$C$1001,)=ROW($1:$1001),ROW($1:$1001),4^8),ROW(C6)))&""} -> while | G6: =IF(F6="",0,1) -> 1
B7: =IFERROR(B6+LEN(C7)+1,"") -> 38 | C7: =IFERROR(MID($A$1,B6+1,FIND(" ",$A$1,B6+1)-B6-1),"") -> others | E7: =IF(C7="",0,1) -> 1 | F7: {=INDEX(C:C,SMALL(IF(MATCH($C$1:$C$1001,$C$1:$C$1001,)=ROW($1:$1001),ROW($1:$1001),4^8),ROW(C7)))&""} -> others | G7: =IF(F7="",0,1) -> 1
B8: =IFERROR(B7+LEN(C8)+1,"") -> 44 | C8: =IFERROR(MID($A$1,B7+1,FIND(" ",$A$1,B7+1)-B7-1),"") -> catch | E8: =IF(C8="",0,1) -> 1 | F8: {=INDEX(C:C,SMALL(IF(MATCH($C$1:$C$1001,$C$1:$C$1001,)=ROW($1:$1001),ROW($1:$1001),4^8),ROW(C8)))&""} -> catch | G8: =IF(F8="",0,1) -> 1
B9: =IFERROR(B8+LEN(C9)+1,"") -> 46 | C9: =IFERROR(MID($A$1,B8+1,FIND(" ",$A$1,B8+1)-B8-1),"") -> a | E9: =IF(C9="",0,1) -> 1 | F9: {=INDEX(C:C,SMALL(IF(MATCH($C$1:$C$1001,$C$1:$C$1001,)=ROW($1:$1001),ROW($1:$1001),4^8),ROW(C9)))&""} -> a | G9: =IF(F9="",0,1) -> 1
B10: =IFERROR(B9+LEN(C10)+1,"") -> 50 | C10: =IFERROR(MID($A$1,B9+1,FIND(" ",$A$1,B9+1)-B9-1),"") -> bus | E10: =IF(C10="",0,1) -> 1 | F10: {=INDEX(C:C,SMALL(IF(MATCH($C$1:$C$1001,$C$1:$C$1001,)=ROW($1:$1001),ROW($1:$1001),4^8),ROW(C10)))&""} -> bus | G10: =IF(F10="",0,1) -> 1
B11: =IFERROR(B10+LEN(C11)+1,"") -> 53 | C11: =IFERROR(MID($A$1,B10+1,FIND(" ",$A$1,B10+1)-B10-1),"") -> or | E11: =IF(C11="",0,1) -> 1 | F11: {=INDEX(C:C,SMALL(IF(MATCH($C$1:$C$1001,$C$1:$C$1001,)=ROW($1:$1001),ROW($1:$1001),4^8),ROW(C11)))&""} -> or | G11: =IF(F11="",0,1) -> 1
B12: =IFERROR(B11+LEN(C12)+1,"") -> 58 | C12: =IFERROR(MID($A$1,B11+1,FIND(" ",$A$1,B11+1)-B11-1),"") -> take | E12: =IF(C12="",0,1) -> 1 | F12: {=INDEX(C:C,SMALL(IF(MATCH($C$1:$C$1001,$C$1:$C$1001,)=ROW($1:$1001),ROW($1:$1001),4^8),ROW(C12)))&""} -> take | G12: =IF(F12="",0,1) -> 1
B13: =IFERROR(B12+LEN(C13)+1,"") -> 62 | C13: =IFERROR(MID($A$1,B12+1,FIND(" ",$A$1,B12+1)-B12-1),"") -> the | E13: =IF(C13="",0,1) -> 1 | F13: {=INDEX(C:C,SMALL(IF(MATCH($C$1:$C$1001,$C$1:$C$1001,)=ROW($1:$1001),ROW($1:$1001),4^8),ROW(C13)))&""} -> the | G13: =IF(F13="",0,1) -> 1
B14: =IFERROR(B13+LEN(C14)+1,"") -> 68 | C14: =IFERROR(MID($A$1,B13+1,FIND(" ",$A$1,B13+1)-B13-1),"") -> train | E14: =IF(C14="",0,1) -> 1 | F14: {=INDEX(C:C,SMALL(IF(MATCH($C$1:$C$1001,$C$1:$C$1001,)=ROW($1:$1001),ROW($1:$1001),4^8),ROW(C14)))&""} -> train | G14: =IF(F14="",0,1) -> 1
B15: =IFERROR(B14+LEN(C15)+1,"") -> 72 | C15: =IFERROR(MID($A$1,B14+1,FIND(" ",$A$1,B14+1)-B14-1),"") -> But | E15: =IF(C15="",0,1) -> 1 | F15: {=INDEX(C:C,SMALL(IF(MATCH($C$1:$C$1001,$C$1:$C$1001,)=ROW($1:$1001),ROW($1:$1001),4^8),ROW(C15)))&""} -> But | G15: =IF(F15="",0,1) -> 1
... B1001: =IFERROR(B1000+LEN(C1001)+1,"") -> 2696 | C1001: =IFERROR(MID($A$1,B1000+1,FIND(" ",$A$1,B1000+1)-B1000-1),"") | E1001: =IF(C1001="",0,1) -> 0 | F1001: {=INDEX(C:C,SMALL(IF(MATCH($C$1:$C$1001,$C$1:$C$1001,)=ROW($1:$1001),ROW($1:$1001),4^8),ROW(C1001)))&""} | G1001: =IF(F1001="",0,1) -> 0
G1002: =SUM(G1:G1001) -> 214

Sheet 3500
A1: ='text process sheet'!A1 -> Some kids walk to school while others catch a bus or take the train But in eight year old Farrokh had to get on a ship to go to his new school He caught a train that rattled and jolted its way out of the dusty city and into the lush green hills He couldn t help thinking that he was getting further away from his family with every mile… What would it be like at his new school He worried about this for the whole journey He was also anxious that the other pupils might make fun of his teeth Would anybody want to be his friend After a bone shaking journey he and nineteen other new students found themselves at the gates of St Peter s School in Panchgani It looked very nice with red roofed buildings surrounded by beautiful green gardens Above the gate was the school s symbol – a bird rising out of the flames Farrokh knew that it was the mythical phoenix which was reborn out of a fire He felt inspired by the wonderful creature The teachers welcomed the students in and showed them their dormitory That night the boy couldn t get to sleep because he missed his family so much Farrokh didn t realise that many of the other boys felt just as lonely as he did He eventually plucked up the courage to start chatting with the other pupils covering his teeth with his hand He soon made some new friends His teachers believed that the best way to help students who were homesick was to distract them with sports and activities Farrokh tried boxing and chess and ping pong – and discovered that he was good at all of them He also loved to win Then there were drama classes Though Farrokh felt nervous when talking to others it was different when he stepped onto the stage The boy loved putting on costumes and swaggering around like royalty Even better than drama though was music The students had to take part in choir practice and that was when the music teacher noticed that Farrokh had an extraordinary voice He hit every note perfectly I think you should have piano lessons the music teacher told him His tutor taught him about jazz and classical music which were wonderful to listen to | C1: ='text process sheet'!C1 -> Some | D1: ='text process sheet'!E1 -> 1
A2: a | B2: =SUMIF(C:C,A2,D:D) -> 6 | C2: ='text process sheet'!C2 -> kids | D2: ='text process sheet'!E2 -> 1
A3: an | B3: =SUMIF(C:C,A3,D:D) -> 1 | C3: ='text process sheet'!C3 -> walk | D3: ='text process sheet'!E3 -> 1
A4: abandon | B4: =SUMIF(C:C,A4,D:D) -> 0 | C4: ='text process sheet'!C4 -> to | D4: ='text process sheet'!E4 -> 1
A5: abandoned | B5: =SUMIF(C:C,A5,D:D) -> 0 | C5: ='text process sheet'!C5 -> school | D5: ='text process sheet'!E5 -> 1
A6: abandoning | B6: =SUMIF(C:C,A6,D:D) -> 0 | C6: ='text process sheet'!C6 -> while | D6: ='text process sheet'!E6 -> 1
A7: abandonment | B7: =SUMIF(C:C,A7,D:D) -> 0 | C7: ='text process sheet'!C7 -> others | D7: ='text process sheet'!E7 -> 1
A8: abandons | B8: =SUMIF(C:C,A8,D:D) -> 0 | C8: ='text process sheet'!C8 -> catch | D8: ='text process sheet'!E8 -> 1
A9: able | B9: =SUMIF(C:C,A9,D:D) -> 0 | C9: ='text process sheet'!C9 -> a | D9: ='text process sheet'!E9 -> 1
A10: abilities | B10: =SUMIF(C:C,A10,D:D) -> 0 | C10: ='text process sheet'!C10 -> bus | D10: ='text process sheet'!E10 -> 1
A11: ability | B11: =SUMIF(C:C,A11,D:D) -> 0 | C11: ='text process sheet'!C11 -> or | D11: ='text process sheet'!E11 -> 1
A12: abler | B12: =SUMIF(C:C,A12,D:D) -> 0 | C12: ='text process sheet'!C12 -> take | D12: ='text process sheet'!E12 -> 1
A13: ablest | B13: =SUMIF(C:C,A13,D:D) -> 0 | C13: ='text process sheet'!C13 -> the | D13: ='text process sheet'!E13 -> 1
... A17168: Z | B17168: =SUMIF(C:C,A17168,D:D) -> 0 | C17168: ='text process sheet'!C17168 -> 0 | D17168: ='text process sheet'!E17168 -> 0
B17169: =SUMIF(C:C,A17169,D:D) -> 0 | C17169: ='text process sheet'!C17169 -> 0 | D17169: ='text process sheet'!E17169 -> 0
B17170: =SUMIF(C:C,A17170,D:D) -> 0 | C17170: ='text process sheet'!C17170 -> 0 | D17170: ='text process sheet'!E17170 -> 0
B17171: =SUMIF(C:C,A17171,D:D) -> 0 | C17171: ='text process sheet'!C17171 -> 0 | D17171: ='text process sheet'!E17171 -> 0
B17172: =SUMIF(C:C,A17172,D:D) -> 0 | C17172: ='text process sheet'!C17172 -> 0 | D17172: ='text process sheet'!E17172 -> 0
B17173: =SUMIF(C:C,A17173,D:D) -> 0 | C17173: ='text process sheet'!C17173 -> 0 | D17173: ='text process sheet'!E17173 -> 0
B17174: =SUMIF(C:C,A17174,D:D) -> 0 | C17174: ='text process sheet'!C17174 -> 0 | D17174: ='text process sheet'!E17174 -> 0
B17175: =SUMIF(C:C,A17175,D:D) -> 0 | C17175: ='text process sheet'!C17175 -> 0 | D17175: ='text process sheet'!E17175 -> 0
B17176: =SUMIF(C:C,A17176,D:D) -> 0 | C17176: ='text process sheet'!C17176 -> 0 | D17176: ='text process sheet'!E17176 -> 0
B17177: =SUMIF(C:C,A17177,D:D) -> 0 | C17177: ='text process sheet'!C17177 -> 0 | D17177: ='text process sheet'!E17177 -> 0
B17178: =SUMIF(C:C,A17178,D:D) -> 0 | C17178: ='text process sheet'!C17178 -> 0 | D17178: ='text process sheet'!E17178 -> 0
B17179: =SUMIF(C:C,A17179,D:D) -> 0 | C17179: ='text process sheet'!C17179 -> 0 | D17179: ='text process sheet'!E17179 -> 0
B17180: =SUMIF(C:C,A17180,D:D) -> 0 | C17180: ='text process sheet'!C17180 -> 0 | D17180: ='text process sheet'!E17180 -> 0
... B17278: =SUMIF(C:C,A17278,D:D) -> 0 | C17278: ='text process sheet'!C17278 -> 0 | D17278: ='text process sheet'!E17278 -> 0
B17287: =SUM(B2:B17286) -> 378 | D17287: =SUM(D1:D17286) -> 390

Sheet 义教
B1: sum | C1: ='text process sheet'!C1 -> Some | D1: =IF(C1="",0,1) -> 1 | E1: CHECK
A2: a | B2: =SUMIF(C:C,A2,D:D) -> 6 | C2: ='text process sheet'!C2 -> kids | D2: =IF(C2="",0,1) -> 1 | E2: =COUNTIF(必修!A:A,A2) -> 0
A3: an | B3: =SUMIF(C:C,A3,D:D) -> 1 | C3: ='text process sheet'!C3 -> walk | D3: =IF(C3="",0,1) -> 1 | E3: =COUNTIF(必修!A:A,A3) -> 0
A4: able | B4: =SUMIF(C:C,A4,D:D) -> 0 | C4: ='text process sheet'!C4 -> to | D4: =IF(C4="",0,1) -> 1 | E4: =COUNTIF(必修!A:A,A4) -> 0
A5: abilities | B5: =SUMIF(C:C,A5,D:D) -> 0 | C5: ='text process sheet'!C5 -> school | D5: =IF(C5="",0,1) -> 1 | E5: =COUNTIF(必修!A:A,A5) -> 0
A6: ability | B6: =SUMIF(C:C,A6,D:D) -> 0 | C6: ='text process sheet'!C6 -> while | D6: =IF(C6="",0,1) -> 1 | E6: =COUNTIF(必修!A:A,A6) -> 0
A7: abler | B7: =SUMIF(C:C,A7,D:D) -> 0 | C7: ='text process sheet'!C7 -> others | D7: =IF(C7="",0,1) -> 1 | E7: =COUNTIF(必修!A:A,A7) -> 0
A8: ablest | B8: =SUMIF(C:C,A8,D:D) -> 0 | C8: ='text process sheet'!C8 -> catch | D8: =IF(C8="",0,1) -> 1 | E8: =COUNTIF(必修!A:A,A8) -> 0
A9: ably | B9: =SUMIF(C:C,A9,D:D) -> 0 | C9: ='text process sheet'!C9 -> a | D9: =IF(C9="",0,1) -> 1 | E9: =COUNTIF(必修!A:A,A9) -> 0
A10: inability | B10: =SUMIF(C:C,A10,D:D) -> 0 | C10: ='text process sheet'!C10 -> bus | D10: =IF(C10="",0,1) -> 1 | E10: =COUNTIF(必修!A:A,A10) -> 0
A11: unable | B11: =SUMIF(C:C,A11,D:D) -> 0 | C11: ='text process sheet'!C11 -> or | D11: =IF(C11="",0,1) -> 1 | E11: =COUNTIF(必修!A:A,A11) -> 0
A12: about | B12: =SUMIF(C:C,A12,D:D) -> 2 | C12: ='text process sheet'!C12 -> take | D12: =IF(C12="",0,1) -> 1 | E12: =COUNTIF(必修!A:A,A12) -> 0
A13: above | B13: =SUMIF(C:C,A13,D:D) -> 1 | C13: ='text process sheet'!C13 -> the | D13: =IF(C13="",0,1) -> 1 | E13: =COUNTIF(必修!A:A,A13) -> 0
... A38: accordingly | B38: =SUMIF(C:C,A38,D:D) -> 0 | C38: ='text process sheet'!C38 -> rattled | D38: =IF(C38="",0,1) -> 1 | E38: =COUNTIF(必修!A:A,A38) -> 0
A39: achieve | B39: =SUMIF(C:C,A39,D:D) -> 0 | C39: ='text process sheet'!C39 -> and | D39: =IF(C39="",0,1) -> 1 | E39: =COUNTIF(必修!A:A,#REF!) -> 0
A40: achievable | B40: =SUMIF(C:C,A40,D:D) -> 0 | C40: ='text process sheet'!C40 -> jolted | D40: =IF(C40="",0,1) -> 1 | E40: =COUNTIF(必修!A:A,A39) -> 1
A41: achieved | B41: =SUMIF(C:C,A41,D:D) -> 0 | C41: ='text process sheet'!C41 -> its | D41: =IF(C41="",0,1) -> 1 | E41: =COUNTIF(必修!A:A,A40) -> 1
A42: achievement | B42: =SUMIF(C:C,A42,D:D) -> 0 | C42: ='text process sheet'!C42 -> way | D42: =IF(C42="",0,1) -> 1 | E42: =COUNTIF(必修!A:A,A41) -> 1
A43: achievements | B43: =SUMIF(C:C,A43,D:D) -> 0 | C43: ='text process sheet'!C43 -> out | D43: =IF(C43="",0,1) -> 1 | E43: =COUNTIF(必修!A:A,A42) -> 1
A44: achiever | B44: =SUMIF(C:C,A44,D:D) -> 0 | C44: ='text process sheet'!C44 -> of | D44: =IF(C44="",0,1) -> 1 | E44: =COUNTIF(必修!A:A,A43) -> 1
A45: achievers | B45: =SUMIF(C:C,A45,D:D) -> 0 | C45: ='text process sheet'!C45 -> the | D45: =IF(C45="",0,1) -> 1 | E45: =COUNTIF(必修!A:A,A44) -> 1
A46: achieves | B46: =SUMIF(C:C,A46,D:D) -> 0 | C46: ='text process sheet'!C46 -> dusty | D46: =IF(C46="",0,1) -> 1 | E46: =COUNTIF(必修!A:A,A45) -> 1
A47: achieving | B47: =SUMIF(C:C,A47,D:D) -> 0 | C47: ='text process sheet'!C47 -> city | D47: =IF(C47="",0,1) -> 1 | E47: =COUNTIF(必修!A:A,A46) -> 1
A48: unachievable | B48: =SUMIF(C:C,A48,D:D) -> 0 | C48: ='text process sheet'!C48 -> and | D48: =IF(C48="",0,1) -> 1 | E48: =COUNTIF(必修!A:A,A47) -> 1
A49: across | B49: =SUMIF(C:C,A49,D:D) -> 0 | C49: ='text process sheet'!C49 -> into | D49: =IF(C49="",0,1) -> 1 | E49: =COUNTIF(必修!A:A,A48) -> 1
A50: act | B50: =SUMIF(C:C,A50,D:D) -> 0 | C50: ='text process sheet'!C50 -> the | D50: =IF(C50="",0,1) -> 1 | E50: =COUNTIF(必修!A:A,A49) -> 0
A51: acted | B51: =SUMIF(C:C,A51,D:D) -> 0 | C51: ='text process sheet'!C51 -> lush | D51: =IF(C51="",0,1) -> 1 | E51: =COUNTIF(必修!A:A,A50) -> 0
... A1000: chocolates | B1000: =SUMIF(C:C,A1000,D:D) -> 0 | C1000: ='text process sheet'!C1000 | D1000: =IF(C1000="",0,1) -> 0 | E1000: =COUNTIF(必修!A:A,A999) -> 0
A1001: chocolatey | B1001: =SUMIF(C:C,A1001,D:D) -> 0
A1002: chocs | B1002: =SUMIF(C:C,A1002,D:D) -> 0
A1003: choice | B1003: =SUMIF(C:C,A1003,D:D) -> 0
A1004: choices | B1004: =SUMIF(C:C,A1004,D:D) -> 0
A1005: choicest | B1005: =SUMIF(C:C,A1005,D:D) -> 0
A1006: choose | B1006: =SUMIF(C:C,A1006,D:D) -> 0
A1007: chooses | B1007: =SUMIF(C:C,A1007,D:D) -> 0
A1008: choosing | B1008: =SUMIF(C:C,A1008,D:D) -> 0
A1009: choosy | B1009: =SUMIF(C:C,A1009,D:D) -> 0
A1010: chose | B1010: =SUMIF(C:C,A1010,D:D) -> 0
A1011: chosen | B1011: =SUMIF(C:C,A1011,D:D) -> 0
A1012: unchosen | B1012: =SUMIF(C:C,A1012,D:D) -> 0
...

Sheet 必修
B1: sum | C1: sum义教 | D1: ='text process sheet'!C1 -> Some | E1: ='text process sheet'!E1 -> 1
A2: absolute | B2: =SUMIF(D:D,A2,E:E)-C2 -> 0 | C2: =SUMIF(义教!A:A,A2,义教!B:B) -> 0 | D2: ='text process sheet'!C2 -> kids | E2: ='text process sheet'!E2 -> 1
A3: absolutely | B3: =SUMIF(D:D,A3,E:E)-C3 -> 0 | C3: =SUMIF(义教!A:A,A3,义教!B:B) -> 0 | D3: ='text process sheet'!C3 -> walk | E3: ='text process sheet'!E3 -> 1
A4: absolutes | B4: =SUMIF(D:D,A4,E:E)-C4 -> 0 | C4: =SUMIF(义教!A:A,A4,义教!B:B) -> 0 | D4: ='text process sheet'!C4 -> to | E4: ='text process sheet'!E4 -> 1
A5: absolutism | B5: =SUMIF(D:D,A5,E:E)-C5 -> 0 | C5: =SUMIF(义教!A:A,A5,义教!B:B) -> 0 | D5: ='text process sheet'!C5 -> school | E5: ='text process sheet'!E5 -> 1
A6: absolutist | B6: =SUMIF(D:D,A6,E:E)-C6 -> 0 | C6: =SUMIF(义教!A:A,A6,义教!B:B) -> 0 | D6: ='text process sheet'!C6 -> while | E6: ='text process sheet'!E6 -> 1
A7: absolutists | B7: =SUMIF(D:D,A7,E:E)-C7 -> 0 | C7: =SUMIF(义教!A:A,A7,义教!B:B) -> 0 | D7: ='text process sheet'!C7 -> others | E7: ='text process sheet'!E7 -> 1
A8: accident | B8: =SUMIF(D:D,A8,E:E)-C8 -> 0 | C8: =SUMIF(义教!A:A,A8,义教!B:B) -> 0 | D8: ='text process sheet'!C8 -> catch | E8: ='text process sheet'!E8 -> 1
A9: accidental | B9: =SUMIF(D:D,A9,E:E)-C9 -> 0 | C9: =SUMIF(义教!A:A,A9,义教!B:B) -> 0 | D9: ='text process sheet'!C9 -> a | E9: ='text process sheet'!E9 -> 1
A10: accidentally | B10: =SUMIF(D:D,A10,E:E)-C10 -> 0 | C10: =SUMIF(义教!A:A,A10,义教!B:B) -> 0 | D10: ='text process sheet'!C10 -> bus | E10: ='text process sheet'!E10 -> 1
A11: accidently | B11: =SUMIF(D:D,A11,E:E)-C11 -> 0 | C11: =SUMIF(义教!A:A,A11,义教!B:B) -> 0 | D11: ='text process sheet'!C11 -> or | E11: ='text process sheet'!E11 -> 1
A12: accidents | B12: =SUMIF(D:D,A12,E:E)-C12 -> 0 | C12: =SUMIF(义教!A:A,A12,义教!B:B) -> 0 | D12: ='text process sheet'!C12 -> take | E12: ='text process sheet'!E12 -> 1
A13: account | B13: =SUMIF(D:D,A13,E:E)-C13 -> 0 | C13: =SUMIF(义教!A:A,A13,义教!B:B) -> 0 | D13: ='text process sheet'!C13 -> the | E13: ='text process sheet'!E13 -> 1
... A3262: effects | B3262: =SUMIF(D:D,A3262,E:E)-C3262 -> 0 | C3262: =SUMIF(义教!A:A,A3262,义教!B:B) -> 0 | D3262: ='text process sheet'!C3262 -> 0 | E3262: ='text process sheet'!E3262 -> 0
B3263: =SUMIF(D:D,A3263,E:E)-C3263 -> 0 | C3263: =SUMIF(义教!A:A,A3263,义教!B:B) -> 0 | D3263: ='text process sheet'!C3263 -> 0 | E3263: ='text process sheet'!E3263 -> 0
B3264: =SUMIF(D:D,A3264,E:E)-C3264 -> 0 | C3264: =SUMIF(义教!A:A,A3264,义教!B:B) -> 0 | D3264: ='text process sheet'!C3264 -> 0 | E3264: ='text process sheet'!E3264 -> 0
B3265: =SUMIF(D:D,A3265,E:E)-C3265 -> 0 | C3265: =SUMIF(义教!A:A,A3265,义教!B:B) -> 0 | D3265: ='text process sheet'!C3265 -> 0 | E3265: ='text process sheet'!E3265 -> 0
B3266: =SUMIF(D:D,A3266,E:E)-C3266 -> 0 | C3266: =SUMIF(义教!A:A,A3266,义教!B:B) -> 0 | D3266: ='text process sheet'!C3266 -> 0 | E3266: ='text process sheet'!E3266 -> 0
B3267: =SUMIF(D:D,A3267,E:E)-C3267 -> 0 | C3267: =SUMIF(义教!A:A,A3267,义教!B:B) -> 0 | D3267: ='text process sheet'!C3267 -> 0 | E3267: ='text process sheet'!E3267 -> 0
B3268: =SUMIF(D:D,A3268,E:E)-C3268 -> 0 | C3268: =SUMIF(义教!A:A,A3268,义教!B:B) -> 0 | D3268: ='text process sheet'!C3268 -> 0 | E3268: ='text process sheet'!E3268 -> 0
B3269: =SUMIF(D:D,A3269,E:E)-C3269 -> 0 | C3269: =SUMIF(义教!A:A,A3269,义教!B:B) -> 0 | D3269: ='text process sheet'!C3269 -> 0 | E3269: ='text process sheet'!E3269 -> 0
B3270: =SUMIF(D:D,A3270,E:E)-C3270 -> 0 | C3270: =SUMIF(义教!A:A,A3270,义教!B:B) -> 0 | D3270: ='text process sheet'!C3270 -> 0 | E3270: ='text process sheet'!E3270 -> 0
B3271: =SUMIF(D:D,A3271,E:E)-C3271 -> 0 | C3271: =SUMIF(义教!A:A,A3271,义教!B:B) -> 0 | D3271: ='text process sheet'!C3271 -> 0 | E3271: ='text process sheet'!E3271 -> 0
B3272: =SUMIF(D:D,A3272,E:E)-C3272 -> 0 | C3272: =SUMIF(义教!A:A,A3272,义教!B:B) -> 0 | D3272: ='text process sheet'!C3272 -> 0 | E3272: ='text process sheet'!E3272 -> 0
B3273: =SUMIF(D:D,A3273,E:E)-C3273 -> 0 | C3273: =SUMIF(义教!A:A,A3273,义教!B:B) -> 0 | D3273: ='text process sheet'!C3273 -> 0 | E3273: ='text process sheet'!E3273 -> 0
B3274: =SUMIF(D:D,A3274,E:E)-C3274 -> 0 | C3274: =SUMIF(义教!A:A,A3274,义教!B:B) -> 0 | D3274: ='text process sheet'!C3274 -> 0 | E3274: ='text process sheet'!E3274 -> 0
... B13040: =SUMIF(D:D,A13040,E:E)-C13040 -> 0 | C13040: =SUMIF(义教!A:A,A13040,义教!B:B) -> 0 | D13040: ='text process sheet'!C13040 -> 0 | E13040: ='text process sheet'!E13040 -> 0
B14000: =SUM(B2:B10001)-C14000 -> 8

Sheet 选择性必修
A1: ='text process sheet'!A1 -> Some kids walk to school while others catch a bus or take the train But in eight year old Farrokh had to get on a ship to go to his new school He caught a train that rattled and jolted its way out of the dusty city and into the lush green hills He couldn t help thinking that he was getting further away from his family with every mile… What would it be like at his new school He worried about this for the whole journey He was also anxious that the other pupils might make fun of his teeth Would anybody want to be his friend After a bone shaking journey he and nineteen other new students found themselves at the gates of St Peter s School in Panchgani It looked very nice with red roofed buildings surrounded by beautiful green gardens Above the gate was the school s symbol – a bird rising out of the flames Farrokh knew that it was the mythical phoenix which was reborn out of a fire He felt inspired by the wonderful creature The teachers welcomed the students in and showed them their dormitory That night the boy couldn t get to sleep because he missed his family so much Farrokh didn t realise that many of the other boys felt just as lonely as he did He eventually plucked up the courage to start chatting with the other pupils covering his teeth with his hand He soon made some new friends His teachers believed that the best way to help students who were homesick was to distract them with sports and activities Farrokh tried boxing and chess and ping pong – and discovered that he was good at all of them He also loved to win Then there were drama classes Though Farrokh felt nervous when talking to others it was different when he stepped onto the stage The boy loved putting on costumes and swaggering around like royalty Even better than drama though was music The students had to take part in choir practice and that was when the music teacher noticed that Farrokh had an extraordinary voice He hit every note perfectly I think you should have piano lessons the music teacher told him His tutor taught him about jazz and classical music which were wonderful to listen to | B1: sum | C1: sum义教 | D1: sum必修 | E1: ='text process sheet'!C1 -> Some | F1: ='text process sheet'!E1 -> 1 | G1: CHECK
A2: abandon | B2: =SUMIF(E:E,A2,F:F)-C2-D2 -> 0 | C2: =SUMIF(义教!A:A,A2,义教!B:B) -> 0 | D2: =SUMIF(必修!A:A,A2,必修!B:B) -> 0 | E2: ='text process sheet'!C2 -> kids | F2: ='text process sheet'!E2 -> 1 | G2: =COUNTIF(义教!A:A,A2) -> 0
A3: abandoned | B3: =SUMIF(E:E,A3,F:F)-C3-D3 -> 0 | C3: =SUMIF(义教!A:A,A3,义教!B:B) -> 0 | D3: =SUMIF(必修!A:A,A3,必修!B:B) -> 0 | E3: ='text process sheet'!C3 -> walk | F3: ='text process sheet'!E3 -> 1 | G3: =COUNTIF(义教!A:A,A3) -> 0
A4: abandoning | B4: =SUMIF(E:E,A4,F:F)-C4-D4 -> 0 | C4: =SUMIF(义教!A:A,A4,义教!B:B) -> 0 | D4: =SUMIF(必修!A:A,A4,必修!B:B) -> 0 | E4: ='text process sheet'!C4 -> to | F4: ='text process sheet'!E4 -> 1 | G4: =COUNTIF(义教!A:A,A4) -> 0
A5: abandonment | B5: =SUMIF(E:E,A5,F:F)-C5-D5 -> 0 | C5: =SUMIF(义教!A:A,A5,义教!B:B) -> 0 | D5: =SUMIF(必修!A:A,A5,必修!B:B) -> 0 | E5: ='text process sheet'!C5 -> school | F5: ='text process sheet'!E5 -> 1 | G5: =COUNTIF(义教!A:A,A5) -> 0
A6: abandons | B6: =SUMIF(E:E,A6,F:F)-C6-D6 -> 0 | C6: =SUMIF(义教!A:A,A6,义教!B:B) -> 0 | D6: =SUMIF(必修!A:A,A6,必修!B:B) -> 0 | E6: ='text process sheet'!C6 -> while | F6: ='text process sheet'!E6 -> 1 | G6: =COUNTIF(义教!A:A,A6) -> 0
A7: abnormal | B7: =SUMIF(E:E,A7,F:F)-C7-D7 -> 0 | C7: =SUMIF(义教!A:A,A7,义教!B:B) -> 0 | D7: =SUMIF(必修!A:A,A7,必修!B:B) -> 0 | E7: ='text process sheet'!C7 -> others | F7: ='text process sheet'!E7 -> 1 | G7: =COUNTIF(义教!A:A,A7) -> 0
A8: abnormalities | B8: =SUMIF(E:E,A8,F:F)-C8-D8 -> 0 | C8: =SUMIF(义教!A:A,A8,义教!B:B) -> 0 | D8: =SUMIF(必修!A:A,A8,必修!B:B) -> 0 | E8: ='text process sheet'!C8 -> catch | F8: ='text process sheet'!E8 -> 1 | G8: =COUNTIF(义教!A:A,A8) -> 0
A9: abnormality | B9: =SUMIF(E:E,A9,F:F)-C9-D9 -> 0 | C9: =SUMIF(义教!A:A,A9,义教!B:B) -> 0 | D9: =SUMIF(必修!A:A,A9,必修!B:B) -> 0 | E9: ='text process sheet'!C9 -> a | F9: ='text process sheet'!E9 -> 1 | G9: =COUNTIF(义教!A:A,A9) -> 0
A10: abnormally | B10: =SUMIF(E:E,A10,F:F)-C10-D10 -> 0 | C10: =SUMIF(义教!A:A,A10,义教!B:B) -> 0 | D10: =SUMIF(必修!A:A,A10,必修!B:B) -> 0 | E10: ='text process sheet'!C10 -> bus | F10: ='text process sheet'!E10 -> 1 | G10: =COUNTIF(义教!A:A,A10) -> 0
A11: aboard | B11: =SUMIF(E:E,A11,F:F)-C11-D11 -> 0 | C11: =SUMIF(义教!A:A,A11,义教!B:B) -> 0 | D11: =SUMIF(必修!A:A,A11,必修!B:B) -> 0 | E11: ='text process sheet'!C11 -> or | F11: ='text process sheet'!E11 -> 1 | G11: =COUNTIF(义教!A:A,A11) -> 0
A12: absence | B12: =SUMIF(E:E,A12,F:F)-C12-D12 -> 0 | C12: =SUMIF(义教!A:A,A12,义教!B:B) -> 0 | D12: =SUMIF(必修!A:A,A12,必修!B:B) -> 0 | E12: ='text process sheet'!C12 -> take | F12: ='text process sheet'!E12 -> 1 | G12: =COUNTIF(义教!A:A,A12) -> 0
A13: absences | B13: =SUMIF(E:E,A13,F:F)-C13-D13 -> 0 | C13: =SUMIF(义教!A:A,A13,义教!B:B) -> 0 | D13: =SUMIF(必修!A:A,A13,必修!B:B) -> 0 | E13: ='text process sheet'!C13 -> the | F13: ='text process sheet'!E13 -> 1 | G13: =COUNTIF(义教!A:A,A13) -> 0
... A1187: faiths | B1187: =SUMIF(E:E,A1187,F:F)-C1187-D1187 -> 0 | C1187: =SUMIF(义教!A:A,A1187,义教!B:B) -> 0 | D1187: =SUMIF(必修!A:A,A1187,必修!B:B) -> 0 | E1187: ='text process sheet'!C1187 -> 0 | F1187: ='text process sheet'!E1187 -> 0 | G1187: =COUNTIF(义教!A:A,A1187) -> 0
A1188: FALSE | B1188: =SUMIF(E:E,A1188,F:F)-C1188-D1188 -> 0 | C1188: =SUMIF(义教!A:A,A1188,义教!B:B) -> 0 | D1188: =SUMIF(必修!A:A,A1188,必修!B:B) -> 0 | E1188: ='text process sheet'!C1188 -> 0 | F1188: ='text process sheet'!E1188 -> 0 | G1188: =COUNTIF(义教!A:A,A1188) -> 0
A1189: falses | B1189: =SUMIF(E:E,A1189,F:F)-C1189-D1189 -> 0 | C1189: =SUMIF(义教!A:A,A1189,义教!B:B) -> 0 | D1189: =SUMIF(必修!A:A,A1189,必修!B:B) -> 0 | E1189: ='text process sheet'!C1189 -> 0 | F1189: ='text process sheet'!E1189 -> 0 | G1189: =COUNTIF(义教!A:A,A1189) -> 0
A1190: fantasy | B1190: =SUMIF(E:E,A1190,F:F)-C1190-D1190 -> 0 | C1190: =SUMIF(义教!A:A,A1190,义教!B:B) -> 0 | D1190: =SUMIF(必修!A:A,A1190,必修!B:B) -> 0 | E1190: ='text process sheet'!C1190 -> 0 | F1190: ='text process sheet'!E1190 -> 0 | G1190: =COUNTIF(义教!A:A,A1190) -> 0
A1191: fantasies | B1191: =SUMIF(E:E,A1191,F:F)-C1191-D1191 -> 0 | C1191: =SUMIF(义教!A:A,A1191,义教!B:B) -> 0 | D1191: =SUMIF(必修!A:A,A1191,必修!B:B) -> 0 | E1191: ='text process sheet'!C1191 -> 0 | F1191: ='text process sheet'!E1191 -> 0 | G1191: =COUNTIF(义教!A:A,A1191) -> 0
A1192: fashion | B1192: =SUMIF(E:E,A1192,F:F)-C1192-D1192 -> 0 | C1192: =SUMIF(义教!A:A,A1192,义教!B:B) -> 0 | D1192: =SUMIF(必修!A:A,A1192,必修!B:B) -> 0 | E1192: ='text process sheet'!C1192 -> 0 | F1192: ='text process sheet'!E1192 -> 0 | G1192: =COUNTIF(义教!A:A,A1192) -> 0
A1193: fashioned | B1193: =SUMIF(E:E,A1193,F:F)-C1193-D1193 -> 0 | C1193: =SUMIF(义教!A:A,A1193,义教!B:B) -> 0 | D1193: =SUMIF(必修!A:A,A1193,必修!B:B) -> 0 | E1193: ='text process sheet'!C1193 -> 0 | F1193: ='text process sheet'!E1193 -> 0 | G1193: =COUNTIF(义教!A:A,A1193) -> 0
A1194: fashions | B1194: =SUMIF(E:E,A1194,F:F)-C1194-D1194 -> 0 | C1194: =SUMIF(义教!A:A,A1194,义教!B:B) -> 0 | D1194: =SUMIF(必修!A:A,A1194,必修!B:B) -> 0 | E1194: ='text process sheet'!C1194 -> 0 | F1194: ='text process sheet'!E1194 -> 0 | G1194: =COUNTIF(义教!A:A,A1194) -> 0
A1195: fashioning | B1195: =SUMIF(E:E,A1195,F:F)-C1195-D1195 -> 0 | C1195: =SUMIF(义教!A:A,A1195,义教!B:B) -> 0 | D1195: =SUMIF(必修!A:A,A1195,必修!B:B) -> 0 | E1195: ='text process sheet'!C1195 -> 0 | F1195: ='text process sheet'!E1195 -> 0 | G1195: =COUNTIF(义教!A:A,A1195) -> 0
A1196: fault | B1196: =SUMIF(E:E,A1196,F:F)-C1196-D1196 -> 0 | C1196: =SUMIF(义教!A:A,A1196,义教!B:B) -> 0 | D1196: =SUMIF(必修!A:A,A1196,必修!B:B) -> 0 | E1196: ='text process sheet'!C1196 -> 0 | F1196: ='text process sheet'!E1196 -> 0 | G1196: =COUNTIF(义教!A:A,A1196) -> 0
A1197: faults | B1197: =SUMIF(E:E,A1197,F:F)-C1197-D1197 -> 0 | C1197: =SUMIF(义教!A:A,A1197,义教!B:B) -> 0 | D1197: =SUMIF(必修!A:A,A1197,必修!B:B) -> 0 | E1197: ='text process sheet'!C1197 -> 0 | F1197: ='text process sheet'!E1197 -> 0 | G1197: =COUNTIF(义教!A:A,A1197) -> 0
A1198: faulted | B1198: =SUMIF(E:E,A1198,F:F)-C1198-D1198 -> 0 | C1198: =SUMIF(义教!A:A,A1198,义教!B:B) -> 0 | D1198: =SUMIF(必修!A:A,A1198,必修!B:B) -> 0 | E1198: ='text process sheet'!C1198 -> 0 | F1198: ='text process sheet'!E1198 -> 0 | G1198: =COUNTIF(义教!A:A,A1198) -> 0
A1199: faulting | B1199: =SUMIF(E:E,A1199,F:F)-C1199-D1199 -> 0 | C1199: =SUMIF(义教!A:A,A1199,义教!B:B) -> 0 | D1199: =SUMIF(必修!A:A,A1199,必修!B:B) -> 0 | E1199: ='text process sheet'!C1199 -> 0 | F1199: ='text process sheet'!E1199 -> 0 | G1199: =COUNTIF(义教!A:A,A1199) -> 0
A1200: favor | B1200: =SUMIF(E:E,A1200,F:F)-C1200-D1200 -> 0 | C1200: =SUMIF(义教!A:A,A1200,义教!B:B) -> 0 | D1200: =SUMIF(必修!A:A,A1200,必修!B:B) -> 0 | E1200: ='text process sheet'!C1200 -> 0 | F1200: ='text process sheet'!E1200 -> 0 | G1200: =COUNTIF(义教!A:A,A1200) -> 0
... A6241: emphases | B6241: =SUMIF(E:E,A6241,F:F)-C6241-D6241 -> 0 | C6241: =SUMIF(义教!A:A,A6241,义教!B:B) -> 0 | D6241: =SUMIF(必修!A:A,A6241,必修!B:B) -> 0 | E6241: ='text process sheet'!C6241 -> 0 | F6241: ='text process sheet'!E6241 -> 0 | G6241: =COUNTIF(义教!A:A,A6241) -> 0
B8000: =SUM(B1:B7999)-C8000-D8000 -> 12

Sheet 合成词
A1: 词汇 | B1: sum | C1: ='text process sheet'!C1 -> Some | D1: ='text process sheet'!E1 -> 1 | E1: CHECK
A2: accountability | B2: =SUMIF(C:C,A2,D:D) -> 0 | C2: ='text process sheet'!C2 -> kids | D2: ='text process sheet'!E2 -> 1 | E2: =COUNTIF(义教!A:A,A2) -> 0 | F2: =LEN(A2) -> 14
A3: accountabilities | B3: =SUMIF(C:C,A3,D:D) -> 0 | C3: ='text process sheet'!C3 -> walk | D3: ='text process sheet'!E3 -> 1 | E3: =COUNTIF(义教!A:A,A3) -> 0 | F3: =LEN(A3) -> 16
A4: adaptability | B4: =SUMIF(C:C,A4,D:D) -> 0 | C4: ='text process sheet'!C4 -> to | D4: ='text process sheet'!E4 -> 1 | E4: =COUNTIF(义教!A:A,A4) -> 0 | F4: =LEN(A4) -> 12
A5: affordability | B5: =SUMIF(C:C,A5,D:D) -> 0 | C5: ='text process sheet'!C5 -> school | D5: ='text process sheet'!E5 -> 1 | E5: =COUNTIF(义教!A:A,A5) -> 1 | F5: =LEN(A5) -> 13
A6: capability | B6: =SUMIF(C:C,A6,D:D) -> 0 | C6: ='text process sheet'!C6 -> while | D6: ='text process sheet'!E6 -> 1 | E6: =COUNTIF(义教!A:A,A6) -> 0 | F6: =LEN(A6) -> 10
A7: capabilities | B7: =SUMIF(C:C,A7,D:D) -> 0 | C7: ='text process sheet'!C7 -> others | D7: ='text process sheet'!E7 -> 1 | E7: =COUNTIF(义教!A:A,A7) -> 0 | F7: =LEN(A7) -> 12
A8: dependability | B8: =SUMIF(C:C,A8,D:D) -> 0 | C8: ='text process sheet'!C8 -> catch | D8: ='text process sheet'!E8 -> 1 | E8: =COUNTIF(义教!A:A,A8) -> 1 | F8: =LEN(A8) -> 13
A9: marketability | B9: =SUMIF(C:C,A9,D:D) -> 0 | C9: ='text process sheet'!C9 -> a | D9: ='text process sheet'!E9 -> 1 | E9: =COUNTIF(义教!A:A,A9) -> 1 | F9: =LEN(A9) -> 13
A10: portability | B10: =SUMIF(C:C,A10,D:D) -> 0 | C10: ='text process sheet'!C10 -> bus | D10: ='text process sheet'!E10 -> 1 | E10: =COUNTIF(义教!A:A,A10) -> 0 | F10: =LEN(A10) -> 11
A11: predictability | B11: =SUMIF(C:C,A11,D:D) -> 0 | C11: ='text process sheet'!C11 -> or | D11: ='text process sheet'!E11 -> 1 | E11: =COUNTIF(义教!A:A,A11) -> 0 | F11: =LEN(A11) -> 14
A12: profitability | B12: =SUMIF(C:C,A12,D:D) -> 0 | C12: ='text process sheet'!C12 -> take | D12: ='text process sheet'!E12 -> 1 | E12: =COUNTIF(义教!A:A,A12) -> 0 | F12: =LEN(A12) -> 13
A13: profitabilities | B13: =SUMIF(C:C,A13,D:D) -> 0 | C13: ='text process sheet'!C13 -> the | D13: ='text process sheet'!E13 -> 1 | E13: =COUNTIF(义教!A:A,A13) -> 0 | F13: =LEN(A13) -> 15
... A271: riverbanks | B271: =SUMIF(C:C,A271,D:D) -> 0 | C271: ='text process sheet'!C271 -> and | D271: ='text process sheet'!E271 -> 1 | E271: =COUNTIF(义教!A:A,A271) -> 0 | F271: =LEN(A271) -> 10
B272: =SUMIF(C:C,A272,D:D) -> 0 | C272: ='text process sheet'!C272 -> activities | D272: ='text process sheet'!E272 -> 1 | E272: =COUNTIF(义教!A:A,A272) -> 0 | F272: =LEN(A272) -> 0
B273: =SUMIF(C:C,A273,D:D) -> 0 | C273: ='text process sheet'!C273 -> Farrokh | D273: ='text process sheet'!E273 -> 1 | E273: =COUNTIF(义教!A:A,A273) -> 0 | F273: =LEN(A273) -> 0
B274: =SUMIF(C:C,A274,D:D) -> 0 | C274: ='text process sheet'!C274 -> tried | D274: ='text process sheet'!E274 -> 1 | E274: =COUNTIF(义教!A:A,A274) -> 0 | F274: =LEN(A274) -> 0
B275: =SUMIF(C:C,A275,D:D) -> 0 | C275: ='text process sheet'!C275 -> boxing | D275: ='text process sheet'!E275 -> 1 | E275: =COUNTIF(义教!A:A,A275) -> 0 | F275: =LEN(A275) -> 0
A276: handlebar | B276: =SUMIF(C:C,A276,D:D) -> 0 | C276: ='text process sheet'!C276 -> and | D276: ='text process sheet'!E276 -> 1 | E276: =COUNTIF(义教!A:A,A276) -> 0 | F276: =LEN(A276) -> 9
A277: handlebars | B277: =SUMIF(C:C,A277,D:D) -> 0 | C277: ='text process sheet'!C277 -> chess | D277: ='text process sheet'!E277 -> 1 | E277: =COUNTIF(义教!A:A,A277) -> 0 | F277: =LEN(A277) -> 10
A278: sandbar | B278: =SUMIF(C:C,A278,D:D) -> 0 | C278: ='text process sheet'!C278 -> and | D278: ='text process sheet'!E278 -> 1 | E278: =COUNTIF(义教!A:A,A278) -> 0 | F278: =LEN(A278) -> 7
A279: sandbars | B279: =SUMIF(C:C,A279,D:D) -> 0 | C279: ='text process sheet'!C279 -> ping | D279: ='text process sheet'!E279 -> 1 | E279: =COUNTIF(义教!A:A,A279) -> 0 | F279: =LEN(A279) -> 8
A280: sidebar | B280: =SUMIF(C:C,A280,D:D) -> 0 | C280: ='text process sheet'!C280 -> pong | D280: ='text process sheet'!E280 -> 1 | E280: =COUNTIF(义教!A:A,A280) -> 0 | F280: =LEN(A280) -> 7
A281: sidebars | B281: =SUMIF(C:C,A281,D:D) -> 0 | C281: ='text process sheet'!C281 -> – | D281: ='text process sheet'!E281 -> 1 | E281: =COUNTIF(义教!A:A,A281) -> 0 | F281: =LEN(A281) -> 8
A282: toolbar | B282: =SUMIF(C:C,A282,D:D) -> 0 | C282: ='text process sheet'!C282 -> and | D282: ='text process sheet'!E282 -> 1 | E282: =COUNTIF(义教!A:A,A282) -> 0 | F282: =LEN(A282) -> 7
A283: toolbars | B283: =SUMIF(C:C,A283,D:D) -> 0 | C283: ='text process sheet'!C283 -> discovered | D283: ='text process sheet'!E283 -> 1 | E283: =COUNTIF(义教!A:A,A283) -> 0 | F283: =LEN(A283) -> 8
A284: airbase | B284: =SUMIF(C:C,A284,D:D) -> 0 | C284: ='text process sheet'!C284 -> that | D284: ='text process sheet'!E284 -> 1 | E284: =COUNTIF(义教!A:A,A284) -> 0 | F284: =LEN(A284) -> 7
A285: airbases | B285: =SUMIF(C:C,A285,D:D) -> 0 | C285: ='text process sheet'!C285 -> he | D285: ='text process sheet'!E285 -> 1 | E285: =COUNTIF(义教!A:A,A285) -> 0 | F285: =LEN(A285) -> 8
A286: wheelbase | B286: =SUMIF(C:C,A286,D:D) -> 0 | C286: ='text process sheet'!C286 -> was | D286: ='text process sheet'!E286 -> 1 | E286: =COUNTIF(义教!A:A,A286) -> 0 | F286: =LEN(A286) -> 9
A287: washbasin | B287: =SUMIF(C:C,A287,D:D) -> 0 | C287: ='text process sheet'!C287 -> good | D287: ='text process sheet'!E287 -> 1 | E287: =COUNTIF(义教!A:A,A287) -> 0 | F287: =LEN(A287) -> 9
... A297: heartbeats | B297: =SUMIF(C:C,A297,D:D) -> 0 | C297: ='text process sheet'!C297 -> Then | D297: ='text process sheet'!E297 -> 1 | E297: =COUNTIF(义教!A:A,A297) -> 0 | F297: =LEN(A297) -> 10
B298: =SUMIF(C:C,A298,D:D) -> 0 | C298: ='text process sheet'!C298 -> there | D298: ='text process sheet'!E298 -> 1 | E298: =COUNTIF(义教!A:A,A298) -> 0 | F298: =LEN(A298) -> 0
A299: daybed | B299: =SUMIF(C:C,A299,D:D) -> 0 | C299: ='text process sheet'!C299 -> were | D299: ='text process sheet'!E299 -> 1 | E299: =COUNTIF(义教!A:A,A299) -> 0 | F299: =LEN(A299) -> 6
A300: daybeds | B300: =SUMIF(C:C,A300,D:D) -> 0 | C300: ='text process sheet'!C300 -> drama | D300: ='text process sheet'!E300 -> 1 | E300: =COUNTIF(义教!A:A,A300) -> 0 | F300: =LEN(A300) -> 7
A301: deathbed | B301: =SUMIF(C:C,A301,D:D) -> 0 | C301: ='text process sheet'!C301 -> classes | D301: ='text process sheet'!E301 -> 1 | E301: =COUNTIF(义教!A:A,A301) -> 0 | F301: =LEN(A301) -> 8
A302: deathbeds | B302: =SUMIF(C:C,A302,D:D) -> 0 | C302: ='text process sheet'!C302 -> Though | D302: ='text process sheet'!E302 -> 1 | E302: =COUNTIF(义教!A:A,A302) -> 0 | F302: =LEN(A302) -> 9
A303: hotbed | B303: =SUMIF(C:C,A303,D:D) -> 0 | C303: ='text process sheet'!C303 -> Farrokh | D303: ='text process sheet'!E303 -> 1 | E303: =COUNTIF(义教!A:A,A303) -> 0 | F303: =LEN(A303) -> 6
A304: hotbeds | B304: =SUMIF(C:C,A304,D:D) -> 0 | C304: ='text process sheet'!C304 -> felt | D304: ='text process sheet'!E304 -> 1 | E304: =COUNTIF(义教!A:A,A304) -> 0 | F304: =LEN(A304) -> 7
A305: riverbed | B305: =SUMIF(C:C,A305,D:D) -> 0 | C305: ='text process sheet'!C305 -> nervous | D305: ='text process sheet'!E305 -> 1 | E305: =COUNTIF(义教!A:A,A305) -> 0 | F305: =LEN(A305) -> 8
A306: riverbeds | B306: =SUMIF(C:C,A306,D:D) -> 0 | C306: ='text process sheet'!C306 -> when | D306: ='text process sheet'!E306 -> 1 | E306: =COUNTIF(义教!A:A,A306) -> 0 | F306: =LEN(A306) -> 9
...

Sheet names
A1: Abraham | B1: 1
A2: Albert | B2: 1
A3: Alexander | B3: 1
A4: Alexandria | B4: 1
A5: Anna | B5: 1
A6: Anne | B6: 1
A7: Annetta | B7: 1
A8: Annette | B8: 1
A9: Anton | B9: 1
A10: Augusta | B10: 1
A11: Bishop | B11: 1
A12: Boston | B12: 1
... A111: Edna | B111: 1
